
<mujoco model='3-dmodel'>
    <compiler inertiafromgeom='true' angle='degree'/>

    <default>
        <joint limited='true' damping='1' armature='0'  />
        <!--        <geom contype='1' conaffinity='1' condim='1' -->
        <!--              margin="0.001" solref=".02 1" solimp=".8 .8 .01" material="geom"/>-->
        <motor ctrlrange='-.4 .4' ctrllimited='true'/>
    </default>

    <option timestep='0.002' iterations="50" solver="PGS">
        <flag energy="enable"/>
    </option>

    <size nkey='5'/>

    <visual>
        <map fogstart="3" fogend="5" force="0.1"/>
        <quality shadowsize="2048"/>
    </visual>

    <asset>
        <texture type="skybox" builtin="gradient" width="100" height="100" rgb1=".4 .6 .8"
                 rgb2="0 0 0"/>
        <texture name="texgeom" type="cube" builtin="flat" mark="cross" width="127" height="1278"
                 rgb1="0.8 0.6 0.4" rgb2="0.8 0.6 0.4" markrgb="1 1 1" random="0.01"/>
        <texture name="texplane" type="2d" builtin="checker" rgb1=".2 .3 .4" rgb2=".1 0.15 0.2"
                 width="100" height="100"/>

        <material name='MatPlane' reflectance='0.5' texture="texplane" texrepeat="1 1" texuniform="true"/>
        <material name='geom' texture="texgeom" texuniform="true"/>
    </asset>

    <worldbody>
        <geom name='floor' pos='0 0 0.925' size='10 10 0.125' type='plane' material="MatPlane" condim='3'/>


        <body name='torso' pos='0 0 1.4'>
            <light mode='trackcom' directional='false' diffuse='.8 .8 .8' specular='0.3 0.3 0.3' pos='0 0 4.0' dir='0 0 -1'/>

            <joint name='root' type='free' pos='0 0 0' limited='false' damping='0' armature='0' stiffness='0'/>
            <geom name='torso1' type='capsule' fromto='0 -.07 0 0 .07 0'  size='0.07' />

            <geom name='uwaist' type='capsule' fromto='-.01 -.06 -.12 -.01 .06 -.12' size='0.06'/>
            <body name='lwaist' pos='-.01 0 -0.260' quat='1.000 0 -0.002 0' >
                <geom name='lwaist' type='capsule' fromto='0 -.06 0 0 .06 0'  size='0.06' />
                <joint name='abdomen_z' type='hinge' pos='0 0 0.065' axis='0 0 1' range='-60 60' damping='5' stiffness='20' armature='0.02' />

                <body name='pelvis' pos='0 0 -0.165' quat='1.000 0 -0.002 0' >

                    <geom name='butt' type='box'  size='0.15 0.22 0.05' density="4500"/>

                </body>
            </body>
            <body name="head" pos="0 0 0.19">
                <geom name='head' type='sphere' pos='0 0 0' size='.09'/>
                <joint name="head_z" type="hinge" axis="0 0 1" range="-60 60" damping="5" stiffness="0" armature="0.02" pos="0 0 -.11"/>
                <joint name="head_y" type="hinge" axis="0 1 0" range="-20 45" damping="5" stiffness="0" armature="0.02" pos="0 0 -.11"/>
                <body name="eyes" pos="0 0 0">
                    <geom name="l_eye" type="sphere" size=".02" pos="0.095 -0.05 0"/>
                    <geom name="r_eye" type="sphere" size=".02" pos="0.095 0.05 0"/>
                </body>
            </body>

            <body name='right_upper_arm' pos='0 -0.17 0.06' >
                <joint name='right_shoulder1' type='hinge' pos='0 0 0' axis='2 1 1'  range='-60 60' stiffness='1' armature='0.0068' />
                <joint name='right_shoulder2' type='hinge' pos='0 0 0' axis='0 -1 1' range='-60 60' stiffness='1'  armature='0.0051' />
                <geom name='right_uarm1' type='capsule' fromto='0 0 0 .16 -.16 -.16'  size='0.04 0.16' />
                <body name='right_lower_arm' pos='.18 -.18 -.18' >
                    <joint name='right_elbow' type='hinge' pos='0 0 0' axis='0 -1 1' range='-90 50'  stiffness='0' armature='0.0028' />
                    <joint name="right_elbow2" type="hinge" pos="0 0 0" axis="0 0 -1" range="-45 40" stiffness="0" armature="0.0028" />
                    <geom name='right_larm' type='capsule' fromto='0.01 0.01 0.01 .17 .17 .17'  size='0.031' />
                    <body name="right_hand" pos=".18 .18 .18">
                        <geom name='right_hand' type='sphere' size='0.04'/>
                    </body>


                </body>
            </body>
            <body name='left_upper_arm' pos='0 0.17 0.06' >
                <!--                <joint name='left_shoulder1' type='hinge' pos='0 0 0' axis='2 -1 1' range='-60 85' stiffness='1' armature='0.0068' />-->
                <!--                <joint name='left_shoulder2' type='hinge' pos='0 0 0' axis='0 1 1' range='-60 85'  stiffness='1' armature='0.0051' />-->
                <geom name='left_uarm1' type='capsule' fromto='0 0 0 .1 0 -.2'  size='0.04 0.16' />
                <body name='left_lower_arm' pos='.1 0 -.2' >
                    <!--                    <joint name='left_elbow' type='hinge' pos='0 0 0' axis='0 -1 -1' range='-90 50' stiffness='0' armature='0.0028' />-->
                    <!--                    <joint name="left_elbow2" type="hinge" pos="0 0 0" axis="0 0 1" range="-45 40" stiffness="0" armature="0.0028" />-->
                    <geom name='left_larm' type='capsule' fromto='0 0 0. .03 -.15 -.21'  size='0.028' />
                    <!--                    <geom name='left_hand' type='sphere' pos='.18 -.18 .18'  size='0.04'/>-->
                </body>
            </body>
        </body>
        <body name="target" pos="2.6 -0.09 2">
            <geom name='target' type='sphere' pos='0 0 0' size='.065'/>
            <joint name="target_y" type="slide" pos="0 0 0" axis="0 1 0" range="-90 50" stiffness="0" armature="0.0028"/>
            <joint name="target_z" type="slide" pos="0 0 0" axis="0 0 1" range="-90 50" stiffness="0" armature="0.0028"/>
            <joint name="target_x" type="slide" pos="0 0 0" axis="1 0 0" range="-90 50" stiffness="0" armature="0.0028"/>
        </body>
    </worldbody>


    <actuator>

        <motor name='head_z'       gear='50' joint='head_z' />
        <motor name='head_y'       gear='50' joint='head_y' />
        <motor name='abdomen_z'       gear='200' joint='abdomen_z' />

        <motor name='right_shoulder1' gear='120' joint='right_shoulder1' />
        <motor name='right_shoulder2' gear='120' joint='right_shoulder2' />
        <motor name='right_elbow'     gear='75' joint='right_elbow' />
        <motor name='right_elbow2'     gear='75' joint='right_elbow2' />
<!--        <motor name='left_shoulder1'  gear='120' joint='left_shoulder1' />-->
<!--        <motor name='left_shoulder2'  gear='120' joint='left_shoulder2' />-->
<!--        <motor name='left_elbow'      gear='100' joint='left_elbow' />-->
<!--        <motor name='left_elbow2'     gear='100' joint='left_elbow2' />-->

    </actuator>

</mujoco>